# 프로그램 오류

- 에러 또는 오류
  - 프로그램 실행 중 어떤 원인에 의해 오작동, 비정상적으로 종료되는 경우
  - 발생시점에 따라 `컴파일 에러` 와 `런타임 에러`로 나뉜다

  #### 컴파일 에러
   - 컴파일시 발생하는 에러

  #### 런타임 에러
   - 실행시 발생되는 에러
   - 실행시 발생하는 `에러`와 `예외`로 구분
   - 에러(Error)
    - 프로그램 코드에서 수습될 수 없는 심각한 오류
    - EX) 메모리 부족(OutOfMemoryError) , 스택오버플로우(StackOverflowError)
   - 예외(Exception)
    - 프로그램 코드에서 수습될 수 있는 다소 미약한 오류
  #### 논리적 에러
   - 실행은 되지만 의도와 다르게 동작하는것


### 예외 클래스 계층구조

Object클래스는 EXception과 Error클래스의 조상이다.


#### RuntimeExption

- 주로 프로그래머의 실수로 발생된다.
- EX) ArrayIndexOutOfBoundsException(배열범위 벗어남), NullPointerException(null 값인 참조변수 멤버호출)

#### Exception 

- 외부의 영향으로 발생할 수 있는 에러.
- 사용자의 실수같은 외적요인으로 인해 발생할 수 있음
- 존재하지 않는 파일 참조(FileNotFoundException), 클래스 이름 잘못적음(ClassNotFoundException), 입력 데이터 형식이 잘못됨(DataFormatExcetion)


![image](https://user-images.githubusercontent.com/78067072/221392905-5a36c657-91b6-49c1-9a4b-01dcb205f08b.png)


위와 같이 Excepetion 안에 Exception이 들어갈 경우Exception 스코프가 같으니 변수명은 다르게 처리한다.

해당 파일은 [Exception/ExceptionEx1.java](https://github.com/786khk/referenceBasic/edit/main/Exception/ExceptionEx1.java) 에서 확인할 수 있다.



아래와 같은 상황일 경우


![image](https://user-images.githubusercontent.com/78067072/221393725-08450d53-b366-4d18-b1b7-afed7b95df72.png)


연산시 0으로 나눌 수 없어 ArithmeticException이 발생한다.

물론 Math.random()으로 출력결과가 나오다 중단될 수 있다.


위의 코드를 바꿔보자면 아래와 같다

```java

public class ExceptionEx3 {
   
    public static void main(String[] args) {
        int num = 100;
        int result = 0;
    
        for (int i=0; i<10; i++){
            try {
                result = num/(int)( Math.random() * 10);
                System.out.println(result);
                
            } catch (Exception e) {

                System.out.println(0); // 에외일때만  0 출력한다.
               
            }
        }
    }
}

/*
11
14
25
20
0 // 예외
33
50
12
100
0 // 예외

*/


```


for문에서 try~catch를 해야 에러인 부분도 catch가 되어 정상종료가 된다.

해당 파일은  [Exception/ExceptionEx2.java]과  [Exception/ExceptionEx3.java]에서 확인할 수 있다.

 [Exception/ExceptionEx2.java](https://github.com/786khk/referenceBasic/edit/main/Exception/ExceptionEx2.java)
 [Exception/ExceptionEx3.java](https://github.com/786khk/referenceBasic/edit/main/Exception/ExceptionEx3.java)

### try~catch문의 흐름

#### try블럭 내 예외 발생할 경우
 - 일치하는 catch를 찾는다.
 - 일치하는 catch문을 수행한다. 그 다음 try~catch문을 빠져나와 가 다음문장을 계속 실행한다.
 - 일치하는 try catch가 없다면 예외처리가 되니지않음

#### try블럭 내 예외 발생하지 않는 경우
 - catch를 수행하디많고 전체 try~ catch문을 빠져나가 수행을 계속한다.



<hr>

![image](https://user-images.githubusercontent.com/78067072/221394811-3862a5c2-0776-4728-b335-df9a74fe0700.png)


![image](https://user-images.githubusercontent.com/78067072/221394794-f27dde0b-6644-4b20-818e-22fcdbf128e5.png)






<hr>



![image](https://user-images.githubusercontent.com/78067072/221395434-88fe4808-6970-4582-abb8-550dce1330cc.png)



해당 파일은 
 [Exception/ExceptionEx7.java](https://github.com/786khk/referenceBasic/edit/main/Exception/ExceptionEx7.java)  에서 확인할 수 있다.
 
 
 <hr>
 
 
## printStackTrace()와 getMessage()

|||
|---|---|
|printStackTrace() | 예와발생시 호출 스택이었던 메서드 정보와 예외 메세지를 화면에 출력한다.|
|getMessage()|발생한 예외 클래스의 인스턴스에 저장된 메세지를 얻을 수 있다.|


![image](https://user-images.githubusercontent.com/78067072/221395618-0fb6fc30-a83f-4872-a36d-d01978560500.png)


- 얼핏보면 비정상 종료처럼 보이지만 사실은 호출 스택에 대한 정보를 출력해주는것일뿐이다. 정상종료가 되었다.
- 
해당 예제는 [Exception/ExceptionEx8.java](https://github.com/786khk/referenceBasic/edit/main/Exception/ExceptionEx8.java)에서 확인할 수 있다.


### 멀티 catch


```java

try{

}catch(AException | BException e){
  e.method(); // Exception에 선언된 method 호출불가
  if(e instanceof BException){
    BException be = (BException) e;
    be.method()
  }else{
    ...
  }
  
  System.out.println();
}
```

처럼 하나의catch블럭에 여러 Exception을 처리할 수 있다.

- 실제로 어떤 예외가 처리되었는지 구분하기 어렵다.
- 두개이상의 예외 클래스 중 부모, 자식관계에 있다면 조상클래스만 써준다
- 조상 이외의 클래스들만 | 를두고 사용한다.
- 어떤 예외인지 알고싶다면 위와 같이 instanceof를 사용해 구분한다.



### 예외 발생시키기

![image](https://user-images.githubusercontent.com/78067072/221396316-5fd30462-2da6-4146-9b2f-83d4a36f9fcf.png)



- 고의로 발생시킨 예외의 메세지를 전달해 getMessage()를 통해 전달된 메세지를 확인할 수 있음


![image](https://user-images.githubusercontent.com/78067072/221396557-4324f68a-2295-41ca-b6ee-1ea365241885.png)

- 이 예제는 컴파일 에러가 발생해 정상실행되지않음 
- 예외가 처리되어야 할 부분에 예외처리가 안됨



![image](https://user-images.githubusercontent.com/78067072/221396595-42e9a0af-2d89-42b4-8ccf-0a69da769165.png)

- 하지만 위와 같은 사례는 컴파일은 잘 되지만 런타임에러가 발생했다.
- RuntimeException은 프로그래머의 실수에 의한 예외다. 그러기떄문에 강제로 정상종료를 방해하지 않는것이다.
- RuntimeException 클래스 들은 unchecked예외라고, Exception클래스의 자손 클래스들은 checked예외 라고 한다.



### 메서드에 예외선언하기

```java

void methods() throw Exception1,Exception2 ...{
  //메서드 내용
}


```
- 예외가 여러개일 경우 ','로 구분한다.
- 자바에서 메서느 예외처리는 가능성이 있는 예외 클래스를 메서드 선언부에 같이 명시해준다.
- 메서드에 throw 로 예외를 명시하는것은 예외를 전달해 예외처리를 떠캍기는것이다.
- 예외를 전달 받은 메서드가 또다시 자신을 호출한 메서드에 전달할 수 있고 이런식으로 계쏙 호출스택에 있는 메서드들을 따라 전달되고 마지막에있는 main에서도 예외가 처리되장ㄶ으면 main메서드 마저 종료된다.

```java

 public static void main(String[] args) throws Exception {
        methods1();
     /**
      * Exception in thread "main" java.lang.Exception
        at Exception.ExceptionEx12.methods2(ExceptionEx12.java:21)
        at Exception.ExceptionEx12.methods1(ExceptionEx12.java:18)
        at Exception.ExceptionEx12.main(ExceptionEx12.java:6)
      */
      /**
       * 호출 스택에 main, methods1,methods2모두 있었다.
       * 예외가 발생한 곳은 methods2()이다.
       * 
       * 호출스택에 
       * methods2()
       * methods1()
       * main()
       * ㅇ 있는데 ( 스택인 first in last out이기떄문에가장 상위에 있는 main이 가장 아래에 있음)
       *  
       */

    }
    static void methods1() throws Exception{
        methods2();
    }
    static void methods2()throws Exception{
        throw new Exception(); 
        // 예외 강제 발생했지만 try ~ catch문으로 예외처리를 안해줬으니
        // methods2종료되면서 methods1에 예외전달, methods1도 똑같이 예외를 main에 전달
    }
    //비정상 종료


```
해당 코드 예제는   [Exception/ExceptionEx12.java](https://github.com/786khk/referenceBasic/edit/main/Exception/ExceptionEx12.java) 에서 확인할 수 있다.
 

![image](https://user-images.githubusercontent.com/78067072/221401759-86a589bf-a2e0-4073-bdcd-73f9cd8b4ec2.png)
해당 예제는  [Exception/ExceptionEx15.java](https://github.com/786khk/referenceBasic/edit/main/Exception/ExceptionEx15.java)에서 확인할 수 있다.


### finally

- 예외 발생여부에 상관없이 실행되어야 하는 코드를 포함시킬 목적으로 사용
- 자원을 사용했다면 자원을 반환하는 finally 블럭이 된다.



```java

try{

}catch(Exception e){
  
}fianlly{
  
}

```

- 예외가 발생했을 경우 try~ catch~finally 순으로 실행, 예외가 발생하지 않으면 try~ finally으로 실행된다.

![image](https://user-images.githubusercontent.com/78067072/221444952-ec4bd6f9-4f25-4177-9e8a-7881e12c6d85.png)
위 이미지와 같이 try에서, catch에서 공통적이로 실행되어야 하는 기능을 finally블록에서 실행한다.

![image](https://user-images.githubusercontent.com/78067072/221444980-3edbb1c8-b639-4aec-95e1-a71efaadd41a.png)

이렇게 한번만 호출하면 된다.


![image](https://user-images.githubusercontent.com/78067072/221402822-8db22cb7-804c-45da-abdd-f18f824bc0dd.png)

예제는 [Exception/FinallyTest1.java](https://github.com/786khk/referenceBasic/edit/main/Exception/FinallyTest1.java)  [Exception/FinallyTest2.java](https://github.com/786khk/referenceBasic/edit/main/Exception/FinallyTest2.java) 
try블럭에 있는 return 으로 실행은 종료되지만 finally블럭은 실행된다.

자바는 한 줄 한 줄 실행이 되는데 실제로 메인메서드에서 try~catch~ finally를 사용하는 메서드를 호출하는 예제는 아래와 같다.

![image](https://user-images.githubusercontent.com/78067072/221445114-c51c2644-efd5-4f7a-ba0f-45685c1192d4.png)
 [Exception/FinallyTest1.java](https://github.com/786khk/referenceBasic/edit/main/Exception/FinallyTest3.java) 
 
 결과는 아래와 같이 실행되는데 예외가 발생해 종료되어도 finally블럭이 실행 된 후 종료가 된다.
 
 ![image](https://user-images.githubusercontent.com/78067072/221445146-1fba11de-adcb-452a-80a9-16b6eea24176.png)




### 자원 자동 반환 try~catch~resource

- 주로 입출력 클래스들은 사용 후 꼭 닫아줘야 한다. 그래야 사용한 자원이 반환된다.

```java
try{

fis = new FileInputStream("Soket.dat");
dis = new DataInputStream(fis);
...

}catch(IOException ioe){
  ioe.printStackTrace();
  
}finally{
  try{
      if(dis!=null) dis.close()
         
  } catch (IOException e) {
       e.printStackTrace();
 
   }
}

```


위의 구조에는 finally문에 try-catch가 추가되었는데 자원을 반환하던 중 에러가 발생할 수 있어 예오ㅚ를 처리한 구조이다.
하지만 가독성은 좋지않다.
finally에서 예외가 발생되면 첫번째 try블럭이 무시된다.

이점을 개선하기 위해 ` try~catch~resource`이 추가되었다.



```java

try(FileInputStream fis - new FileInputStream("soket.dat");
  DataInputStream dis = new DataInputStream(fis);){

  while(true){
  score = dis.readInt();
  System.out.println(score);
  sum += score;
  }
}catch (Exception e) {
  System.out.println("총합 : " + sum);
} catch (IOException e) {
  e.printStackTrace();
}

```


```java

public static void main(String[] args) {
        try(CloseableResource cr = new CloseableResource()) {
           cr.exceptionWork(false); //close()만 예외
        
        } catch (WorkException e) {
            e.printStackTrace();
        } catch(CloseException e ){
            e.printStackTrace();
        }

        try(CloseableResource cr = new CloseableResource()) {
            cr.exceptionWork(true); //close()와 exceptionWork() 둘 다 예외 발생
            
         
         } catch (WorkException e) {
             e.printStackTrace();
         } catch(CloseException e ){
             e.printStackTrace(); // WorkException 발생 여기서 CloseException도 발생되었지만 `Suppressed`라는 키워드가 있음
             // 두개의 에러를 발생시킬 수 없으니 실제 발생한 예외는 WorkException로 하고 CloseException는 억제된 예외로 다룬다. 
             // 실제 발생한 예외정보는 WorkException에 저정되에 결과에서 WorkException예외에서 스택레이스가 출력된
         }

    }

    static void mathod1(){
        try {
            System.out.println("method1 호출됨");
            return ;
        } catch (Exception e) {
            e.printStackTrace();
        }finally{
            System.out.println("method1 finally 블럭 실행");
        }
    }
  
}
class CloseableResource implements AutoCloseable{
    public void exceptionWork(boolean exception) throws WorkException{
        System.out.println("excetion Work("+ exception +")가 호출됨");
        if(exception) throw new WorkException("WorkException 발생!");
    }
    public void close() throws CloseException{
        System.out.println("close() 호출");
        throw new CloseException("CloseException 발생");
    }
}

class WorkException extends Exception{
    WorkException(String message){super(message);}
}

class CloseException extends Exception{
    CloseException(String message){super(message);}
}



결과 : 

excetion Work(false)가 호출됨
close() 호출
Exception.CloseException: CloseException 발생
        at Exception.CloseableResource.close(TryWithResourceEx.java:46)
        at Exception.TryWithResourceEx.main(TryWithResourceEx.java:8)
excetion Work(true)가 호출됨
close() 호출
Exception.WorkException: WorkException 발생!
        at Exception.CloseableResource.exceptionWork(TryWithResourceEx.java:42)
        at Exception.TryWithResourceEx.main(TryWithResourceEx.java:16)
        Suppressed: Exception.CloseException: CloseException 발생
                at Exception.CloseableResource.close(TryWithResourceEx.java:46)
                at Exception.TryWithResourceEx.main(TryWithResourceEx.java:18)
```



주석을 달아놓았다.

![image](https://user-images.githubusercontent.com/78067072/221446619-3076d75c-8841-406e-b9fe-3ad39cdc5276.png)


결과는 주석에도 잇지만 위 사진같이 나오는데 같은 예외처리지만 아래 Exception.WorkException은 `Suppressed(억제된 예외)`라는 키워드가 보인다.
이부분은 `CloseException`에서 발생한 에러를 억제해 WorkException이 실제 발생한 에러로 하되 CloseException의 에러를 다룬다.

`두 예외가 실제로 발생할 수 없기때문`이다.



### 사용자 정의 예외


- 보통의 예외는  Exception과 RuntimeException 으로부터 상속받아 클래스를 만들지만 사용자의 요건에 맞게 생성가능하다.


```java

class MyException extends Exception{
  MyException(String msg){
    super(msg); // 문자열을 메개변수로 받아 조상인 Exception의 생성자 호출
  }
}
```


```java

class MyException extends Exception{
  private final int ERR_CODE;
  
  MyException(String msg, int errCode){
    super(msg); 
    ERR_CODE = errCode;
  }
  
   MyException(String msg){
    super(msg,100); // 기본값 100으로 초기화
  }
  
  pulic int getErrCode(){ ///에러 코드를 얻을 수 있는메서드
    return ERR_CODE;//getMessage()와 함께 사용
  }
}
```

